<?xml version="1.0" ?>
<robot xmlns:xacro="http://www.ros.org/wiki/xacro" >



    <xacro:property name="cylinder_length" value = "0.053" />
    <xacro:property name="cylinder_radius" value = "0.0704" />
    <xacro:property name="wheel_radius" value = "0.021" />
    <xacro:property name="wheel_len" value = "0.005" />
   
     

    <link name="base_footprint"/>
    <joint name="base_joint" type="fixed">
    <parent link="base_footprint"/>
    <child link="base_link"/>
    <origin xyz="0 0 0.0047" rpy="0 0 0"/>
  </joint>  

 
    <link name="base_link">
       <visual>
           <geometry>
              <cylinder length="${cylinder_length}" radius="${cylinder_radius}"/>
            </geometry>
            <origin xyz="0 0 0.0265" rpy="0 0 0"/>
            <material name="blue"/>
        </visual>
        <collision>
         <geometry>
              <cylinder length="${cylinder_length}" radius="${cylinder_radius}"/>
         </geometry>
          <origin xyz="0 0 0.0265" rpy="0 0 0"/>
        </collision>
        <inertial>
           <mass value="0.5"/>
           <origin xyz="0 0 0.0265" rpy="0 0 0"/>
           <inertia ixx="0.00114" ixy="0" ixz="0" iyy="0.00114" iyz="0" izz="0.000273"/>
        </inertial>  
    </link>

    <!-- Left Wheel -->
 
  <joint name="left_wheel_joint" type="continuous">
    <parent link="base_link"/>
    <child link="left_wheel"/>
    <origin xyz="0 0.0527 0.0163" rpy="0 0 0"/>
    <axis xyz="0 1 0"/>
  </joint>  
 
  <link name="left_wheel">
      <origin xyz="0 0 0" rpy="0 ${pi /2.0} ${pi /2.0}"/>
      <geometry>
        <cylinder length="${wheel_len}" radius="${wheel_radius}"/>
      </geometry>
    <visual name="left_wheel_visual">
      <origin xyz="0 0 0" rpy="0 ${pi /2.0} ${pi /2.0}"/>
      <geometry>
        <cylinder length="0.005" radius="0.021"/>
      </geometry>
      <material name="grey" />
    </visual>
    <collision>
      <geometry>
        <cylinder length="${wheel_len}" radius="${wheel_radius}"/>
      </geometry>
      <origin xyz="0 0 0" rpy="0 ${pi /2.0} ${pi /2.0}"/>
    </collision>
    <inertial>
      <mass value="0.033"/>
      <origin xyz="0 0 0" rpy="0 ${pi /2.0} ${pi /2.0}"/>
      <inertia ixx="0.00000054" ixy="0" ixz="0" iyy="0.00000054" iyz="0" izz="0.00000016"/>
    </inertial>
    
  </link>
   
 
  <!-- Right Wheel -->
 
  <joint name="right_wheel_joint" type="continuous">
    <parent link="base_link"/>
    <child link="right_wheel"/>
    <origin xyz="0 -0.0527 0.0163" rpy="0 0 0"/>
    <axis xyz="0 1 0"/>
  </joint>  
 
  <link name="right_wheel">
    <visual name="right_wheel_visual">
      <origin xyz="0 0 0" rpy="0  ${pi /2.0} ${pi /2.0}"/>
      <geometry>
        <cylinder length="${wheel_len}" radius="${wheel_radius}"/>
      </geometry>
      <material name="grey" />
    </visual>
    <collision>
      <geometry>
        <cylinder length="${wheel_len}" radius="${wheel_radius}"/>
      </geometry>
      <origin xyz="0 0 0" rpy="0 ${pi /2.0} ${pi /2.0}"/>
    </collision>
    <inertial>
      <mass value="0.033"/>
      <origin xyz="0 0 0" rpy="0 ${pi /2.0} ${pi /2.0}"/>
      <inertia ixx="0.00000054" ixy="0" ixz="0" iyy="0.00000054" iyz="0" izz="0.00000016"/>
    </inertial>

  </link>


    <link name="Laser_link">
        <visual>
            <geometry>
                <cylinder length="0.02" radius="0.03"/>
            </geometry>
            <origin xyz="0 0 0" rpy="0 0 0 "/>
            <material name="grey" />
        </visual>
        <collision>
          <geometry>
                <cylinder length="0.02" radius="0.03"/>
          </geometry>
            <origin xyz="0 0 0" rpy="0 0 0 "/>
        </collision>
        <inertial>
           <mass value="0.25"/>
           <origin xyz="0 0 0" rpy="0 0 0"/>
           <inertia ixx="0.000025" ixy="0" ixz="0" iyy="0.000025" iyz="0" izz="0.00001125"/>
        </inertial>
        
    </link>

    <joint name="base_Laser_joint" type="fixed">
          <parent link="base_link" />
          <child link="Laser_link" />
          <origin xyz="0 0 0.063" rpy="0 0 0"/>
    </joint>


    <!-- camera - link -->
    <link name="camera_link">
        <visual>
            <geometry>
                <cylinder length="0.0035" radius="0.009"/>
            </geometry>
            <origin xyz="0 0 0.025" rpy="0 -1.5707  3.14 "/>
            <material name="grey" />
        </visual>
        <collision>
            <geometry>
                <cylinder length="0.0035" radius="0.009"/> 
             </geometry>
        </collision>
        <inertial>
          <mass value="1e-5" />
          <origin xyz="0 0 0" rpy="0 0 0" />
          <inertia ixx="4.05e-11" ixy="0" ixz="0" iyy="4.05e-11" iyz="0" izz="4.05e-11" />
        </inertial>
    </link>

    <joint name="base_camera_joint" type="fixed">
          <parent link="base_link" />
          <child link="camera_link" />
          <origin xyz="0.069 0 0" rpy="0 0 0"/>
    </joint> 


    <!-- caster wheel -->

    <link name="Front_caster_wheel">
        <visual>
            <geometry>
                <sphere radius=".0047"/>
            </geometry>
            <origin xyz="0 0 0" rpy="0 0 0"/>
            <material name="grey" />
        </visual>
        <collision>
          <geometry>
                <sphere radius=".0047"/>
          </geometry>
            <origin xyz="0 0 0" rpy="0 0 0 "/>
        </collision>
        <inertial>
          <mass value="0.033"/>
          <origin xyz="0 0 0" rpy="0 0 0"/>
          <inertia ixx="0.00000065" ixy="0" ixz="0" iyy="0.00000065" iyz="0" izz="0.00000065"/>
       </inertial>


    </link>

    <joint name="F_caster_joint" type="fixed">
          <parent link="base_link" />
          <child link="Front_caster_wheel" />
          <origin xyz="0.05 0 0" rpy="0 0 0"/>
    </joint>



    <link name="Back_caster_wheel">
        <visual>
            <geometry>
                <sphere radius=".0047"/>
            </geometry>
            <origin xyz="0 0 0" rpy="0  0  0"/>
            <material name="grey" />
        </visual>
        <collision>
          <geometry>
                <sphere radius=".0047"/>
          </geometry>
            <origin xyz="0 0 0" rpy="0 0 0 "/>
        </collision>
        <inertial>
          <mass value="0.033"/>
          <origin xyz="0 0 0" rpy="0 0 0"/>
          <inertia ixx="0.00000065" ixy="0" ixz="0" iyy="0.00000065" iyz="0" izz="0.00000065"/>
       </inertial>
    </link>

    <joint name="B_caster_joint" type="fixed">
          <parent link="base_link" />
          <child link="Back_caster_wheel" />
          <origin xyz="-0.05 0 0" rpy="0 0 0"/>
    </joint>



</robot>